<?xml version="1.0" encoding="UTF-8"?>
<testng-results skipped="0" failed="1" ignored="0" total="1" passed="0">
  <reporter-output>
  </reporter-output>
  <suite name="InetBankingV1" duration-ms="25521" started-at="2019-08-06T19:02:13Z" finished-at="2019-08-06T19:02:38Z">
    <groups>
    </groups>
    <test name="Shopping Test" duration-ms="25521" started-at="2019-08-06T19:02:13Z" finished-at="2019-08-06T19:02:38Z">
      <class name="com.testCases.TC_01_Login">
        <test-method status="PASS" signature="setup(java.lang.String)[pri:0, instance:com.testCases.TC_01_Login@3abbfa04]" name="setup" is-config="true" duration-ms="9386" started-at="2019-08-06T19:02:14Z" finished-at="2019-08-06T19:02:23Z">
          <params>
            <param index="0">
              <value>
                <![CDATA[chrome]]>
              </value>
            </param>
          </params>
          <reporter-output>
          </reporter-output>
        </test-method> <!-- setup -->
        <test-method status="FAIL" signature="login()[pri:0, instance:com.testCases.TC_01_Login@3abbfa04]" name="login" duration-ms="13884" started-at="2019-08-06T19:02:23Z" finished-at="2019-08-06T19:02:37Z">
          <exception class="java.lang.AssertionError">
            <message>
              <![CDATA[expected [true] but found [false]]]>
            </message>
            <full-stacktrace>
              <![CDATA[java.lang.AssertionError: expected [true] but found [false]
at org.testng.Assert.fail(Assert.java:96)
at org.testng.Assert.failNotEquals(Assert.java:776)
at org.testng.Assert.assertTrue(Assert.java:44)
at org.testng.Assert.assertTrue(Assert.java:54)
at com.testCases.TC_01_Login.login(TC_01_Login.java:30)
at sun.reflect.NativeMethodAccessorImpl.invoke0(Native Method)
at sun.reflect.NativeMethodAccessorImpl.invoke(NativeMethodAccessorImpl.java:62)
at sun.reflect.DelegatingMethodAccessorImpl.invoke(DelegatingMethodAccessorImpl.java:43)
at java.lang.reflect.Method.invoke(Method.java:498)
at org.testng.internal.MethodInvocationHelper.invokeMethod(MethodInvocationHelper.java:124)
at org.testng.internal.Invoker.invokeMethod(Invoker.java:583)
at org.testng.internal.Invoker.invokeTestMethod(Invoker.java:719)
at org.testng.internal.Invoker.invokeTestMethods(Invoker.java:989)
at org.testng.internal.TestMethodWorker.invokeTestMethods(TestMethodWorker.java:125)
at org.testng.internal.TestMethodWorker.run(TestMethodWorker.java:109)
at org.testng.TestRunner.privateRun(TestRunner.java:648)
at org.testng.TestRunner.run(TestRunner.java:505)
at org.testng.SuiteRunner.runTest(SuiteRunner.java:455)
at org.testng.SuiteRunner.runSequentially(SuiteRunner.java:450)
at org.testng.SuiteRunner.privateRun(SuiteRunner.java:415)
at org.testng.SuiteRunner.run(SuiteRunner.java:364)
at org.testng.SuiteRunnerWorker.runSuite(SuiteRunnerWorker.java:52)
at org.testng.SuiteRunnerWorker.run(SuiteRunnerWorker.java:84)
at org.testng.TestNG.runSuitesSequentially(TestNG.java:1208)
at org.testng.TestNG.runSuitesLocally(TestNG.java:1137)
at org.testng.TestNG.runSuites(TestNG.java:1049)
at org.testng.TestNG.run(TestNG.java:1017)
at org.testng.remote.AbstractRemoteTestNG.run(AbstractRemoteTestNG.java:115)
at org.testng.remote.RemoteTestNG.initAndRun(RemoteTestNG.java:251)
at org.testng.remote.RemoteTestNG.main(RemoteTestNG.java:77)
]]>
            </full-stacktrace>
          </exception> <!-- java.lang.AssertionError -->
          <reporter-output>
          </reporter-output>
        </test-method> <!-- login -->
        <test-method status="PASS" signature="teardown()[pri:0, instance:com.testCases.TC_01_Login@3abbfa04]" name="teardown" is-config="true" duration-ms="1027" started-at="2019-08-06T19:02:37Z" finished-at="2019-08-06T19:02:38Z">
          <reporter-output>
          </reporter-output>
        </test-method> <!-- teardown -->
      </class> <!-- com.testCases.TC_01_Login -->
    </test> <!-- Shopping Test -->
  </suite> <!-- InetBankingV1 -->
</testng-results>
